Workbook

Sheet Take off
A1: Manually input all green fields
A2: Customer Name:
A3: Address:
A4: City / State / Zip:
B7: Pitch | D7: # of Layers | F7: Shingle Manufacturer
B8: 5 | D8: 2 | F8: GAF
D10: Roof Area with pitch factor | E10: Measurements
D11: 2300 | E11: 1. Find area of roof without waste. Break out different areas of different pitches, apply pitch factor.
B14: as measured per roof plan, without pitch factor | C14: OR | D14: with pitch factored in | E14: 2. Find all of the below, without waste:
D15: ="" | E15: Eave length
C16: OR | D16: =SQRT(((($B$8/12)*B16)^2)+B16^2) -> 0 | E16: Rake (some call this Gable) length - multiply by pitch factor
C17: OR | D17: =SQRT(((($B$8/12)*B17)^2)+B17^2) -> 0 | E17: Sidewall length (side of slope ties into vertical wall) – multiply by pitch factor
D18: ="" | E18: Headwall length (top of slope ties into vertical wall)
C19: OR | D19: =SQRT(((($B$8/12)*B19)^2)+B19^2) -> 0 | E19: Valley length – multiply by pitch factor (if 2 different pitches come together, use the steeper of the 2)
C20: OR | D20: =SQRT(((($B$8/12)*B20)^2)+B20^2) -> 0 | E20: Hip length– multiply by pitch factor (if 2 different pitches come together, use the steeper of the 2)
D21: ="" | E21: Ridge length
D22: ="" | E22: # of pipes
D23: ="" | E23: # of Chimney
A25: Waste % | B25: Actual | C25: Coverage | D25: With Waste | E25: Materials
A26: 0.2 | B26: =SUM((D16+B15)/10) -> 0 | D26: =ROUNDUP((((D16+B15)*(1+A26))/10),0) -> 0 | E26: 3. Drip Edge (10’ pcs): Add eave + rake. Add 20% (typically F8 white .019 aluminum)
A27: 0.1 | B27: =SUM((B15*2),(D19+B18+D17),((B22+B23)*3))/67 -> 0 | D27: =ROUNDUP(((B27)*(1+A27)),0) -> 0 | E27: 4. Ice and water shield (67’x3’ or 200 sf rolls) linear footage: Typically, WeatherWatch (Eave x2)+((Valley+Headwall+Sidewall). Add 10 %. Divide by 67’ = # of rolls. LF of Ice and water shield area X 3’ is area needed for step 5.
A28: 0.1 | B28: =(D11-(B27*200))/C28 -> 2.3 | C28: 1000 | D28: =IF(ROUNDUP(((B28)*(1+A28)),0)<0,0,ROUNDUP(((B28)*(1+A28)),0)) -> 3 | E28: 5. Felt Buster (1000 sf rolls): roof area – Ice and water area, from step 4. Add 10 %. Divide by 1000 = # of rolls OR ShingleMate (4’x100’ or 400 sf rolls): roof area – Ice and water area, from step 4. Add 10 %. Divide by 400 = # of rolls
A29: 0.05 | B29: =(D11/100)*C29 -> 23 | C29: 1 | D29: =ROUNDUP(((B29)*(1+A29)),0) -> 25 | E29: 6. Shingles: roof area, add 5%. Divide by 100 = # squares. Multiply by 3 to get # of bundles, or by 1 to get # squares
A30: 0.1 | B30: =(D20+B21)/C30 -> 0 | C30: =IF(F8="GAF",25,30) -> 25 | D30: =ROUNDUP(((B30)*(1+A30)),0) -> 0 | E30: 7. Caps (these vary, TimberTex you get 20’ per bundle, Seal-A-Ridge 25’ per bundle) : Hip +Ridge, add 10%. Divide by quantity in package = # of bundles
A31: 0.1 | B31: =SUM((D16+B15)/C31) -> 0 | C31: =IF(F8="GAF",120,116) -> 120 | D31: =ROUNDUP(((B31)*(1+A31)),0) -> 0 | E31: 8. Starters (these vary too, for Timberline HDs, ProStarts cover 120’ per bundle): Eave + Rake, add 10%. Divide by qty in package = # of bundles. Check requirements for different shingles. WeatherMax 50' or 100'
A32: 0.1 | B32: =IF($D$8=0,(((D17*3)+(B23*12))/100),0) -> 0 | D32: =ROUNDUP(((B32)*(1+A32)),0) -> 0 | E32: 9. Step flashing: Sidewall x 3. Add 10 %. Round up to nearest 100. Divide by 100 = # of packs
A33: 0.1 | B33: =IF($D$8=0,((B18+(B23*4))/200),0) -> 0 | D33: =ROUNDUP(((B33)*(1+A33)),0) -> 0 | E33: 10. Coil stock: Headwall, add 10 %. 200 lf of 6” total girth (3”x3”) is in a 24”x50’ roll.
A34: 0.1 | B34: =(D11/1500) -> 1.5333333 | D34: =ROUNDUP(((B34)*(1+A34)),0) -> 2 | E34: 11. Nails: Shingle squares divide by 15, round up
A35: 0.1 | B35: =(B21)/C35 -> 0 | C35: 4 | D35: =ROUNDUP(((B35)*(1+A35)),0) -> 0 | E35: 12. Ridge vent: ridge divided by 20 = # of 20’ CobraCoils. Or divide by 4 for pieces of SnowCountry/ShingleVent
B36: =B22 -> 0 | D36: =B36 -> 0 | E36: 13. Pipe boots
G37: other costs
B38: 140 | E38: 13. Adjust Labor rate based on chart at bottom left of spreadsheet.
A39: auto-calc | B39: =ROUNDUP((((D11/100)*D8)/50),0) -> 1 | E39: 14. If a tear off, add for dumpsters. 50 sq of single layer can fit in one 30 yd can. 25sq for 2 layers.
E40: 15. Select warranty: System Plus or Golden Pledge (this appears to be broken at the moment)
E41: 16. Other factors: mansard, slates, thicker shingles, degree of difficulty, height (more than 2 stories), deck replacement, etc. This will affect the labor rate. Consult with Robert G
E42: 17. Put in correct financing charge fee
B44: Typical Labor #s | G44: Add ons
A45: 75 | B45: new construction less than 8:12 | F45: 40 | G45: Wood shakes add
A46: 85 | B46: new construction 8:12 and steeper | F46: 250 | G46: Strip/replace valleys only
A47: 195 | B47: New construction mansards | F47: 120 | G47: Mansards add
...

Sheet Timberlines (2 layer strip)
A2: Name: | B2: Tim Lamoureaux Residence
A4: Address: | B4: 195 Rice Corner Road
B5: Brookfield. MA
A7: 1 | B7: All Blue auto-filled from take-off page - make sure make sense
A8: 2 | B8: verify and manually fill in any optional purple products - if used
A9: 3 | B9: 0
B11: 1900 | C11: SF of actual roof area without waste. Includes pitch factor.
B13: Material | C13: Units | D13: UOM | E13: Price | F13: Total | G13: tax | H13: total | I13: marked up 40%
A14: GAF | B14: WeatherWatch (2sq roll)(3x66.6) | C14: 0 | D14: roll | E14: 95 | F14: =SUM(C14)*(E14) -> 0 | G14: =SUM(F14)*0.0625 -> 0 | H14: =SUM(F14:G14) -> 0 | I14: =SUM(H14)*1.4 -> 0
B15: StormGuard (2 sq roll) | D15: roll | E15: 100.71 | F15: =SUM(C15)*(E15) -> 0 | G15: =SUM(F15)*0.0625 -> 0 | H15: =SUM(F15:G15) -> 0 | I15: =SUM(H15)*1.4 -> 0
B16: Felt buster (10 sq coverage) | C16: 0 | D16: roll | E16: 121 | F16: =SUM(C16)*(E16) -> 0 | G16: =SUM(F16)*0.0625 -> 0 | H16: =SUM(F16:G16) -> 0 | I16: =SUM(H16)*1.4 -> 0
B17: Deck Armor (10sq roll) | D17: roll | E17: 200.5 | F17: =SUM(C17)*(E17) -> 0 | G17: =SUM(F17)*0.0625 -> 0 | H17: =SUM(F17:G17) -> 0 | I17: =SUM(H17)*1.4 -> 0
B18: Shingle Mate (4sq roll) | C18: =IF(AND('Take off'!C28=400,'Take off'!F8="GAF"),'Take off'!D28,0) -> 0 | D18: roll | E18: 60.81 | F18: =SUM(C18)*(E18) -> 0 | G18: =SUM(F18)*0.0625 -> 0 | H18: =SUM(F18:G18) -> 0 | I18: =SUM(H18)*1.4 -> 0
B19: Prostart Starter Strip (120lf bundle) | C19: 0 | D19: bundle | E19: 65.75 | F19: =SUM(C19)*(E19) -> 0 | G19: =SUM(F19)*0.0625 -> 0 | H19: =SUM(F19:G19) -> 0 | I19: =SUM(H19)*1.4 -> 0
B20: WeatherBlocker Starter Strip (100lf <6" exp; 50lf bundle >6" exp) | D20: bundle | E20: 60 | F20: =SUM(C20)*(E20) -> 0 | G20: =SUM(F20)*0.0625 -> 0 | H20: =SUM(F20:G20) -> 0 | I20: =SUM(H20)*1.4 -> 0
B21: TRI C SA PlyBase Sheet (2 sq roll) | C21: 0 | D21: roll | E21: 127.5 | F21: =SUM(C21)*(E21) -> 0 | G21: =SUM(F21)*0.0625 -> 0 | H21: =SUM(F21:G21) -> 0 | I21: =SUM(H21)*1.4 -> 0
B22: TRI C SA Cap Sheet (1 sq roll) | C22: 0 | D22: roll | E22: 126.25 | F22: =SUM(C22)*(E22) -> 0 | G22: =SUM(F22)*0.0625 -> 0 | H22: =SUM(F22:G22) -> 0 | I22: =SUM(H22)*1.4 -> 0
B23: GAF-Timberline HDZ | C23: 0 | D23: sq | E23: 144 | F23: =SUM(C23)*(E23) -> 0 | G23: =SUM(F23)*0.0625 -> 0 | H23: =SUM(F23:G23) -> 0 | I23: =SUM(H23)*1.4 -> 0
B24: GAF-Timberline HDZ | C24: =IF(AND('Take off'!C29=3,'Take off'!F8="GAF"),'Take off'!D29,0) -> 0 | D24: bundle | E24: =E23/3 -> 48 | F24: =SUM(C24)*(E24) -> 0 | G24: =SUM(F24)*0.0625 -> 0 | H24: =SUM(F24:G24) -> 0 | I24: =SUM(H24)*1.4 -> 0
B25: GAF- Slateline 30yr | D25: sq | E25: 205 | F25: =SUM(C25)*(E25) -> 0 | G25: =SUM(F25)*0.0625 -> 0 | H25: =SUM(F25:G25) -> 0 | I25: =SUM(H25)*1.4 -> 0
B26: Seal-A-Ridge Caps (25lf/bundle) | C26: 0 | D26: bundle | E26: 76 | F26: =SUM(C26)*(E26) -> 0 | G26: =SUM(F26)*0.0625 -> 0 | H26: =SUM(F26:G26) -> 0 | I26: =SUM(H26)*1.4 -> 0
B27: TimberTex Ridge Caps (20lf/bundle) | C27: 0 | D27: bundle | E27: 108 | F27: =SUM(C27)*(E27) -> 0 | G27: =SUM(F27)*0.0625 -> 0 | H27: =SUM(F27:G27) -> 0 | I27: =SUM(H27)*1.4 -> 0
B28: Cobra Snow Country Advanced Ridge Vent (4' pc) | C28: 0 | D28: ea | E28: 16 | F28: =SUM(C28)*(E28) -> 0 | G28: =SUM(F28)*0.0625 -> 0 | H28: =SUM(F28:G28) -> 0 | I28: =SUM(H28)*1.4 -> 0
B29: Cobra Coil Ridge Vent (20' roll) | C29: =IF(AND('Take off'!C35=20,'Take off'!F8="GAF"),'Take off'!D35,0) -> 0 | D29: roll | E29: 45 | F29: =SUM(C29)*(E29) -> 0 | G29: =SUM(F29)*0.0625 -> 0 | H29: =SUM(F29:G29) -> 0 | I29: =SUM(H29)*1.4 -> 0
A30: CertainTeed | B30: CertainTeed WinterGuard(2 sq roll) | C30: 5 | D30: roll | E30: 90 | F30: =SUM(C30)*(E30) -> 450 | G30: =SUM(F30)*0.0625 -> 28.125 | H30: =SUM(F30:G30) -> 478.125 | I30: =SUM(H30)*1.4 -> 669.375
B31: CertainTeed WinterGuard High Temp(2 sq roll) | D31: roll | E31: 176.32 | F31: =SUM(C31)*(E31) -> 0 | G31: =SUM(F31)*0.0625 -> 0 | H31: =SUM(F31:G31) -> 0 | I31: =SUM(H31)*1.4 -> 0
B32: CertainTeed RoofRunner (10sq roll) | C32: 2 | D32: roll | E32: 114 | F32: =SUM(C32)*(E32) -> 228 | G32: =SUM(F32)*0.0625 -> 14.25 | H32: =SUM(F32:G32) -> 242.25 | I32: =SUM(H32)*1.4 -> 339.15
B33: CertainTeed RoofersSelect (4sq roll) | C33: =IF(AND('Take off'!C28=400,'Take off'!F8="CertainTeed"),'Take off'!D28,0) -> 0 | D33: roll | E33: 63.38 | F33: =SUM(C33)*(E33) -> 0 | G33: =SUM(F33)*0.0625 -> 0 | H33: =SUM(F33:G33) -> 0 | I33: =SUM(H33)*1.4 -> 0
B34: CertainTeed Diamond Deck (10sq roll) | D34: roll | E34: 268.39 | F34: =SUM(C34)*(E34) -> 0 | G34: =SUM(F34)*0.0625 -> 0 | H34: =SUM(F34:G34) -> 0 | I34: =SUM(H34)*1.4 -> 0
B35: SwiftStart Starter Strip (116lf bundle) | C35: 2 | D35: bundle | E35: 62 | F35: =SUM(C35)*(E35) -> 124 | G35: =SUM(F35)*0.0625 -> 7.75 | H35: =SUM(F35:G35) -> 131.75 | I35: =SUM(H35)*1.4 -> 184.45
B36: Hi Perf Starter Strip (100lf bundle) | D36: bundle | E36: 62 | F36: =SUM(C36)*(E36) -> 0 | G36: =SUM(F36)*0.0625 -> 0 | H36: =SUM(F36:G36) -> 0 | I36: =SUM(H36)*1.4 -> 0
B37: CertainTeed Landmark | C37: 0 | D37: sq | E37: 115.41 | F37: =SUM(C37)*(E37) -> 0 | G37: =SUM(F37)*0.0625 -> 0 | H37: =SUM(F37:G37) -> 0 | I37: =SUM(H37)*1.4 -> 0
B38: CertainTeed Landmark Pro | C38: 21 | D38: sq | E38: 147 | F38: =SUM(C38)*(E38) -> 3087 | G38: =SUM(F38)*0.0625 -> 192.9375 | H38: =SUM(F38:G38) -> 3279.9375 | I38: =SUM(H38)*1.4 -> 4591.9125
B39: CertainTeed Premium | D39: sq | E39: 250 | F39: =SUM(C39)*(E39) -> 0 | G39: =SUM(F39)*0.0625 -> 0 | H39: =SUM(F39:G39) -> 0 | I39: =SUM(H39)*1.4 -> 0
B40: Ridge Caps CedarCrest (20lf/bundle) | C40: =IF(AND('Take off'!C30=20,'Take off'!F8="CertainTeed"), 'Take off'!D30,0) -> 0 | D40: bundle | E40: 54 | F40: =SUM(C40)*(E40) -> 0 | G40: =SUM(F40)*0.0625 -> 0 | H40: =SUM(F40:G40) -> 0 | I40: =SUM(H40)*1.4 -> 0
B41: Ridge Caps ShadowRidge (30lf/bundle) | C41: 3 | D41: bundle | E41: 72 | F41: =SUM(C41)*(E41) -> 216 | G41: =SUM(F41)*0.0625 -> 13.5 | H41: =SUM(F41:G41) -> 229.5 | I41: =SUM(H41)*1.4 -> 321.3
B42: 12" filtered Ridge Vent (4' pc) | C42: 17 | D42: ea | E42: 14.57 | F42: =SUM(C42)*(E42) -> 247.69 | G42: =SUM(F42)*0.0625 -> 15.480625 | H42: =SUM(F42:G42) -> 263.17062 | I42: =SUM(H42)*1.4 -> 368.43887
A43: Accessories | B43: 8" white drip edge .019" F8 | C43: 23 | D43: 10' length | E43: 11.5 | F43: =SUM(C43)*(E43) -> 264.5 | G43: =SUM(F43)*0.0625 -> 16.53125 | H43: =SUM(F43:G43) -> 281.03125 | I43: =SUM(H43)*1.4 -> 393.44375
B44: Alum Step Flashing 8x10 (3/lf) | C44: 3 | D44: pack/100 | E44: 62.0391 | F44: =SUM(C44)*(E44) -> 186.1173 | G44: =SUM(F44)*0.0625 -> 11.632331 | H44: =SUM(F44:G44) -> 197.74963 | I44: =SUM(H44)*1.4 -> 276.84948
B45: white 24" x50' roll Alum coilstock | C45: 0 | D45: roll | E45: 139.2303 | F45: =SUM(C45)*(E45) -> 0 | G45: =SUM(F45)*0.0625 -> 0 | H45: =SUM(F45:G45) -> 0 | I45: =SUM(H45)*1.4 -> 0
...

Sheet Timberlines 2 layer strip w-ply
A2: Name: | B2: Samuel Kariuki
A4: Address: | B4: 22 Douglas Street, Worcester MA 01603
B5: =IF('Take off'!C4=0,"",'Take off'!C4)
A7: 1 | B7: All Blue auto-filled from take-off page - make sure make sense
A8: 2 | B8: verify and manually fill in any optional purple products - if used
A9: 3 | B9: Light Green prices current as of 3/1/21
B11: 2700 | C11: SF of actual roof area without waste. Includes pitch factor.
B13: Material | C13: Units | D13: UOM | E13: Price | F13: Total | G13: tax | H13: total | I13: marked up 40%
A14: GAF | B14: WeatherWatch (2sq roll)(3x66.6) | C14: 9 | D14: roll | E14: 77.5997 | F14: =SUM(C14)*(E14) -> 698.3973 | G14: =SUM(F14)*0.0625 -> 43.649831 | H14: =SUM(F14:G14) -> 742.04713 | I14: =SUM(H14)*1.4 -> 1038.866
B15: StormGuard (2 sq roll) | D15: roll | E15: 100.71 | F15: =SUM(C15)*(E15) -> 0 | G15: =SUM(F15)*0.0625 -> 0 | H15: =SUM(F15:G15) -> 0 | I15: =SUM(H15)*1.4 -> 0
B16: Felt buster (10 sq coverage) | C16: 2 | D16: roll | E16: 113.5494 | F16: =SUM(C16)*(E16) -> 227.0988 | G16: =SUM(F16)*0.0625 -> 14.193675 | H16: =SUM(F16:G16) -> 241.29248 | I16: =SUM(H16)*1.4 -> 337.80946
B17: Deck Armor (10sq roll) | D17: roll | E17: 200.5 | F17: =SUM(C17)*(E17) -> 0 | G17: =SUM(F17)*0.0625 -> 0 | H17: =SUM(F17:G17) -> 0 | I17: =SUM(H17)*1.4 -> 0
B18: Shingle Mate (4sq roll) | C18: =IF(AND('Take off'!C28=400,'Take off'!F8="GAF"),'Take off'!D28,0) -> 0 | D18: roll | E18: 60.81 | F18: =SUM(C18)*(E18) -> 0 | G18: =SUM(F18)*0.0625 -> 0 | H18: =SUM(F18:G18) -> 0 | I18: =SUM(H18)*1.4 -> 0
B19: Prostart Starter Strip (120lf bundle) | C19: 4 | D19: bundle | E19: 56.3306 | F19: =SUM(C19)*(E19) -> 225.3224 | G19: =SUM(F19)*0.0625 -> 14.08265 | H19: =SUM(F19:G19) -> 239.40505 | I19: =SUM(H19)*1.4 -> 335.16707
B20: WeatherBlocker Starter Strip (100lf <6" exp; 50lf bundle >6" exp) | D20: bundle | E20: 60 | F20: =SUM(C20)*(E20) -> 0 | G20: =SUM(F20)*0.0625 -> 0 | H20: =SUM(F20:G20) -> 0 | I20: =SUM(H20)*1.4 -> 0
B21: TRI C SA PlyBase Sheet (2 sq roll) | C21: 1 | D21: roll | E21: 127.5 | F21: =SUM(C21)*(E21) -> 127.5 | G21: =SUM(F21)*0.0625 -> 7.96875 | H21: =SUM(F21:G21) -> 135.46875 | I21: =SUM(H21)*1.4 -> 189.65625
B22: TRI C SA Cap Sheet (1 sq roll) | C22: 1 | D22: roll | E22: 126.25 | F22: =SUM(C22)*(E22) -> 126.25 | G22: =SUM(F22)*0.0625 -> 7.890625 | H22: =SUM(F22:G22) -> 134.14062 | I22: =SUM(H22)*1.4 -> 187.79688
B23: GAF-Timberline HDZ | C23: 29 | D23: sq | E23: 126 | F23: =SUM(C23)*(E23) -> 3654 | G23: =SUM(F23)*0.0625 -> 228.375 | H23: =SUM(F23:G23) -> 3882.375 | I23: =SUM(H23)*1.4 -> 5435.325
B24: GAF-Timberline HDZ | C24: =IF(AND('Take off'!C29=3,'Take off'!F8="GAF"),'Take off'!D29,0) -> 0 | D24: bundle | E24: =E23/3 -> 42 | F24: =SUM(C24)*(E24) -> 0 | G24: =SUM(F24)*0.0625 -> 0 | H24: =SUM(F24:G24) -> 0 | I24: =SUM(H24)*1.4 -> 0
B25: GAF- Slateline 30yr | D25: sq | E25: 205 | F25: =SUM(C25)*(E25) -> 0 | G25: =SUM(F25)*0.0625 -> 0 | H25: =SUM(F25:G25) -> 0 | I25: =SUM(H25)*1.4 -> 0
B26: Seal-A-Ridge Caps (25lf/bundle) | C26: 6 | D26: bundle | E26: 59.88 | F26: =SUM(C26)*(E26) -> 359.28 | G26: =SUM(F26)*0.0625 -> 22.455 | H26: =SUM(F26:G26) -> 381.735 | I26: =SUM(H26)*1.4 -> 534.429
B27: TimberTex Ridge Caps (20lf/bundle) | C27: =IF(AND('Take off'!C30=20,'Take off'!F8="GAF"), 'Take off'!D30,0) -> 0 | D27: bundle | E27: 60.59 | F27: =SUM(C27)*(E27) -> 0 | G27: =SUM(F27)*0.0625 -> 0 | H27: =SUM(F27:G27) -> 0 | I27: =SUM(H27)*1.4 -> 0
B28: Cobra Snow Country Advanced Ridge Vent (4' pc) | C28: 26 | D28: ea | E28: 11.8476 | F28: =SUM(C28)*(E28) -> 308.0376 | G28: =SUM(F28)*0.0625 -> 19.25235 | H28: =SUM(F28:G28) -> 327.28995 | I28: =SUM(H28)*1.4 -> 458.20593
B29: Cobra Coil Ridge Vent (20' roll) | C29: =IF(AND('Take off'!C35=20,'Take off'!F8="GAF"),'Take off'!D35,0) -> 0 | D29: roll | E29: 45 | F29: =SUM(C29)*(E29) -> 0 | G29: =SUM(F29)*0.0625 -> 0 | H29: =SUM(F29:G29) -> 0 | I29: =SUM(H29)*1.4 -> 0
A30: CertainTeed | B30: CertainTeed WinterGuard(2 sq roll) | C30: =IF('Take off'!F8="CertainTeed",'Take off'!D27,0) -> 0 | D30: roll | E30: 82.5 | F30: =SUM(C30)*(E30) -> 0 | G30: =SUM(F30)*0.0625 -> 0 | H30: =SUM(F30:G30) -> 0 | I30: =SUM(H30)*1.4 -> 0
B31: CertainTeed WinterGuard High Temp(2 sq roll) | D31: roll | E31: 176.32 | F31: =SUM(C31)*(E31) -> 0 | G31: =SUM(F31)*0.0625 -> 0 | H31: =SUM(F31:G31) -> 0 | I31: =SUM(H31)*1.4 -> 0
B32: CertainTeed RoofRunner (10sq roll) | C32: =IF(AND('Take off'!C28=1000,'Take off'!F8="CertainTeed"),'Take off'!D28,0) -> 0 | D32: roll | E32: 112.65 | F32: =SUM(C32)*(E32) -> 0 | G32: =SUM(F32)*0.0625 -> 0 | H32: =SUM(F32:G32) -> 0 | I32: =SUM(H32)*1.4 -> 0
B33: CertainTeed RoofersSelect (4sq roll) | C33: =IF(AND('Take off'!C28=400,'Take off'!F8="CertainTeed"),'Take off'!D28,0) -> 0 | D33: roll | E33: 63.38 | F33: =SUM(C33)*(E33) -> 0 | G33: =SUM(F33)*0.0625 -> 0 | H33: =SUM(F33:G33) -> 0 | I33: =SUM(H33)*1.4 -> 0
B34: CertainTeed Diamond Deck (10sq roll) | D34: roll | E34: 268.39 | F34: =SUM(C34)*(E34) -> 0 | G34: =SUM(F34)*0.0625 -> 0 | H34: =SUM(F34:G34) -> 0 | I34: =SUM(H34)*1.4 -> 0
B35: SwiftStart Starter Strip (116lf bundle) | C35: =IF(AND('Take off'!C31=116,'Take off'!F8="CertainTeed"),'Take off'!D31,0) -> 0 | D35: bundle | E35: 61.83 | F35: =SUM(C35)*(E35) -> 0 | G35: =SUM(F35)*0.0625 -> 0 | H35: =SUM(F35:G35) -> 0 | I35: =SUM(H35)*1.4 -> 0
B36: Hi Perf Starter Strip (100lf bundle) | D36: bundle | E36: 62 | F36: =SUM(C36)*(E36) -> 0 | G36: =SUM(F36)*0.0625 -> 0 | H36: =SUM(F36:G36) -> 0 | I36: =SUM(H36)*1.4 -> 0
B37: CertainTeed Landmark | C37: =IF(AND('Take off'!C29=1,'Take off'!F8="CertainTeed"),'Take off'!D29,0) -> 0 | D37: sq | E37: 115.41 | F37: =SUM(C37)*(E37) -> 0 | G37: =SUM(F37)*0.0625 -> 0 | H37: =SUM(F37:G37) -> 0 | I37: =SUM(H37)*1.4 -> 0
B38: CertainTeed Landmark Pro | D38: sq | E38: 103.5 | F38: =SUM(C38)*(E38) -> 0 | G38: =SUM(F38)*0.0625 -> 0 | H38: =SUM(F38:G38) -> 0 | I38: =SUM(H38)*1.4 -> 0
B39: CertainTeed Premium | D39: sq | E39: 250 | F39: =SUM(C39)*(E39) -> 0 | G39: =SUM(F39)*0.0625 -> 0 | H39: =SUM(F39:G39) -> 0 | I39: =SUM(H39)*1.4 -> 0
B40: Ridge Caps CedarCrest (20lf/bundle) | C40: =IF(AND('Take off'!C30=20,'Take off'!F8="CertainTeed"), 'Take off'!D30,0) -> 0 | D40: bundle | E40: 54 | F40: =SUM(C40)*(E40) -> 0 | G40: =SUM(F40)*0.0625 -> 0 | H40: =SUM(F40:G40) -> 0 | I40: =SUM(H40)*1.4 -> 0
B41: Ridge Caps ShadowRidge (30lf/bundle) | C41: =IF(AND('Take off'!C30=30,'Take off'!F8="CertainTeed"), 'Take off'!D30,0) -> 0 | D41: bundle | E41: 74.15 | F41: =SUM(C41)*(E41) -> 0 | G41: =SUM(F41)*0.0625 -> 0 | H41: =SUM(F41:G41) -> 0 | I41: =SUM(H41)*1.4 -> 0
B42: 12" filtered Ridge Vent (4' pc) | C42: =IF(AND('Take off'!C35=4,'Take off'!F8="CertainTeed"),'Take off'!D35,0) -> 0 | D42: ea | E42: 14.57 | F42: =SUM(C42)*(E42) -> 0 | G42: =SUM(F42)*0.0625 -> 0 | H42: =SUM(F42:G42) -> 0 | I42: =SUM(H42)*1.4 -> 0
A43: Accessories | B43: 8" white drip edge .019" F8 | C43: 40 | D43: 10' length | E43: 12.7065 | F43: =SUM(C43)*(E43) -> 508.26 | G43: =SUM(F43)*0.0625 -> 31.76625 | H43: =SUM(F43:G43) -> 540.02625 | I43: =SUM(H43)*1.4 -> 756.03675
B44: Alum Step Flashing 8x10 (3/lf) | C44: 3 | D44: pack/100 | E44: 62.0391 | F44: =SUM(C44)*(E44) -> 186.1173 | G44: =SUM(F44)*0.0625 -> 11.632331 | H44: =SUM(F44:G44) -> 197.74963 | I44: =SUM(H44)*1.4 -> 276.84948
B45: white 24" x50' roll Alum coilstock | C45: 1 | D45: roll | E45: 139.2303 | F45: =SUM(C45)*(E45) -> 139.2303 | G45: =SUM(F45)*0.0625 -> 8.7018937 | H45: =SUM(F45:G45) -> 147.93219 | I45: =SUM(H45)*1.4 -> 207.10507
...

Sheet Timberlines (3 layer strip)
A2: Name: | B2: Samuel Kariuki
A4: Address: | B4: 22 Douglas Street, Worcester MA 01603
B5: =IF('Take off'!C4=0,"",'Take off'!C4)
A7: 1 | B7: All Blue auto-filled from take-off page - make sure make sense
A8: 2 | B8: verify and manually fill in any optional purple products - if used
A9: 3 | B9: Light Green prices current as of 3/1/21
B11: 2700 | C11: SF of actual roof area without waste. Includes pitch factor.
B13: Material | C13: Units | D13: UOM | E13: Price | F13: Total | G13: tax | H13: total | I13: marked up 40%
A14: GAF | B14: WeatherWatch (2sq roll)(3x66.6) | C14: 9 | D14: roll | E14: 77.5997 | F14: =SUM(C14)*(E14) -> 698.3973 | G14: =SUM(F14)*0.0625 -> 43.649831 | H14: =SUM(F14:G14) -> 742.04713 | I14: =SUM(H14)*1.4 -> 1038.866
B15: StormGuard (2 sq roll) | D15: roll | E15: 100.71 | F15: =SUM(C15)*(E15) -> 0 | G15: =SUM(F15)*0.0625 -> 0 | H15: =SUM(F15:G15) -> 0 | I15: =SUM(H15)*1.4 -> 0
B16: Felt buster (10 sq coverage) | C16: 2 | D16: roll | E16: 113.5494 | F16: =SUM(C16)*(E16) -> 227.0988 | G16: =SUM(F16)*0.0625 -> 14.193675 | H16: =SUM(F16:G16) -> 241.29248 | I16: =SUM(H16)*1.4 -> 337.80946
B17: Deck Armor (10sq roll) | D17: roll | E17: 200.5 | F17: =SUM(C17)*(E17) -> 0 | G17: =SUM(F17)*0.0625 -> 0 | H17: =SUM(F17:G17) -> 0 | I17: =SUM(H17)*1.4 -> 0
B18: Shingle Mate (4sq roll) | C18: =IF(AND('Take off'!C28=400,'Take off'!F8="GAF"),'Take off'!D28,0) -> 0 | D18: roll | E18: 60.81 | F18: =SUM(C18)*(E18) -> 0 | G18: =SUM(F18)*0.0625 -> 0 | H18: =SUM(F18:G18) -> 0 | I18: =SUM(H18)*1.4 -> 0
B19: Prostart Starter Strip (120lf bundle) | C19: 4 | D19: bundle | E19: 56.3306 | F19: =SUM(C19)*(E19) -> 225.3224 | G19: =SUM(F19)*0.0625 -> 14.08265 | H19: =SUM(F19:G19) -> 239.40505 | I19: =SUM(H19)*1.4 -> 335.16707
B20: WeatherBlocker Starter Strip (100lf <6" exp; 50lf bundle >6" exp) | D20: bundle | E20: 60 | F20: =SUM(C20)*(E20) -> 0 | G20: =SUM(F20)*0.0625 -> 0 | H20: =SUM(F20:G20) -> 0 | I20: =SUM(H20)*1.4 -> 0
B21: TRI C SA PlyBase Sheet (2 sq roll) | C21: 1 | D21: roll | E21: 127.5 | F21: =SUM(C21)*(E21) -> 127.5 | G21: =SUM(F21)*0.0625 -> 7.96875 | H21: =SUM(F21:G21) -> 135.46875 | I21: =SUM(H21)*1.4 -> 189.65625
B22: TRI C SA Cap Sheet (1 sq roll) | C22: 1 | D22: roll | E22: 126.25 | F22: =SUM(C22)*(E22) -> 126.25 | G22: =SUM(F22)*0.0625 -> 7.890625 | H22: =SUM(F22:G22) -> 134.14062 | I22: =SUM(H22)*1.4 -> 187.79688
B23: GAF-Timberline HDZ | C23: 29 | D23: sq | E23: 126 | F23: =SUM(C23)*(E23) -> 3654 | G23: =SUM(F23)*0.0625 -> 228.375 | H23: =SUM(F23:G23) -> 3882.375 | I23: =SUM(H23)*1.4 -> 5435.325
B24: GAF-Timberline HDZ | C24: =IF(AND('Take off'!C29=3,'Take off'!F8="GAF"),'Take off'!D29,0) -> 0 | D24: bundle | E24: =E23/3 -> 42 | F24: =SUM(C24)*(E24) -> 0 | G24: =SUM(F24)*0.0625 -> 0 | H24: =SUM(F24:G24) -> 0 | I24: =SUM(H24)*1.4 -> 0
B25: GAF- Slateline 30yr | D25: sq | E25: 205 | F25: =SUM(C25)*(E25) -> 0 | G25: =SUM(F25)*0.0625 -> 0 | H25: =SUM(F25:G25) -> 0 | I25: =SUM(H25)*1.4 -> 0
B26: Seal-A-Ridge Caps (25lf/bundle) | C26: 6 | D26: bundle | E26: 59.88 | F26: =SUM(C26)*(E26) -> 359.28 | G26: =SUM(F26)*0.0625 -> 22.455 | H26: =SUM(F26:G26) -> 381.735 | I26: =SUM(H26)*1.4 -> 534.429
B27: TimberTex Ridge Caps (20lf/bundle) | C27: =IF(AND('Take off'!C30=20,'Take off'!F8="GAF"), 'Take off'!D30,0) -> 0 | D27: bundle | E27: 60.59 | F27: =SUM(C27)*(E27) -> 0 | G27: =SUM(F27)*0.0625 -> 0 | H27: =SUM(F27:G27) -> 0 | I27: =SUM(H27)*1.4 -> 0
B28: Cobra Snow Country Advanced Ridge Vent (4' pc) | C28: 26 | D28: ea | E28: 11.8476 | F28: =SUM(C28)*(E28) -> 308.0376 | G28: =SUM(F28)*0.0625 -> 19.25235 | H28: =SUM(F28:G28) -> 327.28995 | I28: =SUM(H28)*1.4 -> 458.20593
B29: Cobra Coil Ridge Vent (20' roll) | C29: =IF(AND('Take off'!C35=20,'Take off'!F8="GAF"),'Take off'!D35,0) -> 0 | D29: roll | E29: 45 | F29: =SUM(C29)*(E29) -> 0 | G29: =SUM(F29)*0.0625 -> 0 | H29: =SUM(F29:G29) -> 0 | I29: =SUM(H29)*1.4 -> 0
A30: CertainTeed | B30: CertainTeed WinterGuard(2 sq roll) | C30: =IF('Take off'!F8="CertainTeed",'Take off'!D27,0) -> 0 | D30: roll | E30: 82.5 | F30: =SUM(C30)*(E30) -> 0 | G30: =SUM(F30)*0.0625 -> 0 | H30: =SUM(F30:G30) -> 0 | I30: =SUM(H30)*1.4 -> 0
B31: CertainTeed WinterGuard High Temp(2 sq roll) | D31: roll | E31: 176.32 | F31: =SUM(C31)*(E31) -> 0 | G31: =SUM(F31)*0.0625 -> 0 | H31: =SUM(F31:G31) -> 0 | I31: =SUM(H31)*1.4 -> 0
B32: CertainTeed RoofRunner (10sq roll) | C32: =IF(AND('Take off'!C28=1000,'Take off'!F8="CertainTeed"),'Take off'!D28,0) -> 0 | D32: roll | E32: 112.65 | F32: =SUM(C32)*(E32) -> 0 | G32: =SUM(F32)*0.0625 -> 0 | H32: =SUM(F32:G32) -> 0 | I32: =SUM(H32)*1.4 -> 0
B33: CertainTeed RoofersSelect (4sq roll) | C33: =IF(AND('Take off'!C28=400,'Take off'!F8="CertainTeed"),'Take off'!D28,0) -> 0 | D33: roll | E33: 63.38 | F33: =SUM(C33)*(E33) -> 0 | G33: =SUM(F33)*0.0625 -> 0 | H33: =SUM(F33:G33) -> 0 | I33: =SUM(H33)*1.4 -> 0
B34: CertainTeed Diamond Deck (10sq roll) | D34: roll | E34: 268.39 | F34: =SUM(C34)*(E34) -> 0 | G34: =SUM(F34)*0.0625 -> 0 | H34: =SUM(F34:G34) -> 0 | I34: =SUM(H34)*1.4 -> 0
B35: SwiftStart Starter Strip (116lf bundle) | C35: =IF(AND('Take off'!C31=116,'Take off'!F8="CertainTeed"),'Take off'!D31,0) -> 0 | D35: bundle | E35: 61.83 | F35: =SUM(C35)*(E35) -> 0 | G35: =SUM(F35)*0.0625 -> 0 | H35: =SUM(F35:G35) -> 0 | I35: =SUM(H35)*1.4 -> 0
B36: Hi Perf Starter Strip (100lf bundle) | D36: bundle | E36: 62 | F36: =SUM(C36)*(E36) -> 0 | G36: =SUM(F36)*0.0625 -> 0 | H36: =SUM(F36:G36) -> 0 | I36: =SUM(H36)*1.4 -> 0
B37: CertainTeed Landmark | C37: =IF(AND('Take off'!C29=1,'Take off'!F8="CertainTeed"),'Take off'!D29,0) -> 0 | D37: sq | E37: 115.41 | F37: =SUM(C37)*(E37) -> 0 | G37: =SUM(F37)*0.0625 -> 0 | H37: =SUM(F37:G37) -> 0 | I37: =SUM(H37)*1.4 -> 0
B38: CertainTeed Landmark Pro | D38: sq | E38: 103.5 | F38: =SUM(C38)*(E38) -> 0 | G38: =SUM(F38)*0.0625 -> 0 | H38: =SUM(F38:G38) -> 0 | I38: =SUM(H38)*1.4 -> 0
B39: CertainTeed Premium | D39: sq | E39: 250 | F39: =SUM(C39)*(E39) -> 0 | G39: =SUM(F39)*0.0625 -> 0 | H39: =SUM(F39:G39) -> 0 | I39: =SUM(H39)*1.4 -> 0
B40: Ridge Caps CedarCrest (20lf/bundle) | C40: =IF(AND('Take off'!C30=20,'Take off'!F8="CertainTeed"), 'Take off'!D30,0) -> 0 | D40: bundle | E40: 54 | F40: =SUM(C40)*(E40) -> 0 | G40: =SUM(F40)*0.0625 -> 0 | H40: =SUM(F40:G40) -> 0 | I40: =SUM(H40)*1.4 -> 0
B41: Ridge Caps ShadowRidge (30lf/bundle) | C41: =IF(AND('Take off'!C30=30,'Take off'!F8="CertainTeed"), 'Take off'!D30,0) -> 0 | D41: bundle | E41: 74.15 | F41: =SUM(C41)*(E41) -> 0 | G41: =SUM(F41)*0.0625 -> 0 | H41: =SUM(F41:G41) -> 0 | I41: =SUM(H41)*1.4 -> 0
B42: 12" filtered Ridge Vent (4' pc) | C42: =IF(AND('Take off'!C35=4,'Take off'!F8="CertainTeed"),'Take off'!D35,0) -> 0 | D42: ea | E42: 14.57 | F42: =SUM(C42)*(E42) -> 0 | G42: =SUM(F42)*0.0625 -> 0 | H42: =SUM(F42:G42) -> 0 | I42: =SUM(H42)*1.4 -> 0
A43: Accessories | B43: 8" white drip edge .019" F8 | C43: 40 | D43: 10' length | E43: 12.7065 | F43: =SUM(C43)*(E43) -> 508.26 | G43: =SUM(F43)*0.0625 -> 31.76625 | H43: =SUM(F43:G43) -> 540.02625 | I43: =SUM(H43)*1.4 -> 756.03675
B44: Alum Step Flashing 8x10 (3/lf) | C44: 3 | D44: pack/100 | E44: 62.0391 | F44: =SUM(C44)*(E44) -> 186.1173 | G44: =SUM(F44)*0.0625 -> 11.632331 | H44: =SUM(F44:G44) -> 197.74963 | I44: =SUM(H44)*1.4 -> 276.84948
B45: white 24" x50' roll Alum coilstock | C45: 1 | D45: roll | E45: 139.2303 | F45: =SUM(C45)*(E45) -> 139.2303 | G45: =SUM(F45)*0.0625 -> 8.7018937 | H45: =SUM(F45:G45) -> 147.93219 | I45: =SUM(H45)*1.4 -> 207.10507
...

Sheet Material List
A1: Material | B1: Units | C1: UOM
A2: {=_xlfn._xlws.FILTER('Timberlines (2 layer strip)'!B14:D65,'Timberlines (2 layer strip)'!C14:C65>0,0)} -> CertainTeed WinterGuard(2 sq roll) | B2: 5 | C2: roll
A3: CertainTeed RoofRunner (10sq roll) | B3: 2 | C3: roll
A4: SwiftStart Starter Strip (116lf bundle) | B4: 2 | C4: bundle
A5: CertainTeed Landmark Pro | B5: 21 | C5: sq
A6: Ridge Caps ShadowRidge (30lf/bundle) | B6: 3 | C6: bundle
A7: 12" filtered Ridge Vent (4' pc) | B7: 17 | C7: ea
A8: 8" white drip edge .019" F8 | B8: 23 | C8: 10' length
A9: Alum Step Flashing 8x10 (3/lf) | B9: 3 | C9: pack/100
A10: Geocel 3900 | B10: 6 | C10: tube
A11: 3"-4" universal pipe boot | B11: 2 | C11: pcs
A12: Nails 1-1/4" coil (15sq/box) | B12: 2 | C12: box
A13: chimney lead | B13: 1 | C13: 12" 50lb roll

Sheet Formulas
A1: Trapezoid Calculator
A2: Edge 1 | B2: 30 | C2: ft
A3: Edge 2 | B3: 45 | C3: ft
A4: Height | B4: 20 | C4: ft
A5: Calculated SF | B5: =((B2+B3)/2)*B4 -> 750 | C5: sft
A7: Triangle Calculator
A8: Edge 1 | B8: 30.5 | C8: ft
A9: Edge 2 | B9: 45 | C9: ft
A10: Edge 3 | B10: 40 | C10: ft
A11: Calculated SF | B11: =SQRT(D11*(D11-B8)*(D11-B9)*(D11-B10)) -> 596.77898 | C11: sft | D11: =(B8+B9+B10)/2 -> 57.75
A13: Hypotenuse Calculator
A14: Slope | B14: 9 | C14: in. / ft.
A15: Horizontal Length | B15: 15.25 | C15: ft
A16: Calculated Length | B16: =SQRT((((B14/12)*B15)^2)+B15^2) -> 19.0625 | C16: ft
